Watching for file changes with StatReloader
/Users/edikeifeanyisamuel/Desktop/non_api_projects/welder/welding_project/main/views.py changed, reloading.
Watching for file changes with StatReloader
/Users/edikeifeanyisamuel/Desktop/non_api_projects/welder/welding_project/main/views.py changed, reloading.
Watching for file changes with StatReloader
/Users/edikeifeanyisamuel/Desktop/non_api_projects/welder/welding_project/main/views.py changed, reloading.
Watching for file changes with StatReloader
/Users/edikeifeanyisamuel/Desktop/non_api_projects/welder/welding_project/main/views.py changed, reloading.
Watching for file changes with StatReloader
/Users/edikeifeanyisamuel/Desktop/non_api_projects/welder/welding_project/main/views.py changed, reloading.
Watching for file changes with StatReloader
/Users/edikeifeanyisamuel/Desktop/non_api_projects/welder/welding_project/main/views.py changed, reloading.
Watching for file changes with StatReloader
/Users/edikeifeanyisamuel/Desktop/non_api_projects/welder/welding_project/main/views.py changed, reloading.
Watching for file changes with StatReloader
/Users/edikeifeanyisamuel/Desktop/non_api_projects/welder/welding_project/main/models.py changed, reloading.
Watching for file changes with StatReloader
/Users/edikeifeanyisamuel/Desktop/non_api_projects/welder/welding_project/main/models.py changed, reloading.
Watching for file changes with StatReloader
Watching for file changes with StatReloader
Watching for file changes with StatReloader
Not Found: /track/B4C797388D8A/
Internal Server Error: /quote-request/
Traceback (most recent call last):
  File "/Users/edikeifeanyisamuel/Desktop/non_api_projects/welder/venv/lib/python3.13/site-packages/django/core/handlers/exception.py", line 55, in inner
    response = get_response(request)
  File "/Users/edikeifeanyisamuel/Desktop/non_api_projects/welder/venv/lib/python3.13/site-packages/django/core/handlers/base.py", line 197, in _get_response
    response = wrapped_callback(request, *callback_args, **callback_kwargs)
  File "/Users/edikeifeanyisamuel/Desktop/non_api_projects/welder/welding_project/main/views.py", line 61, in quote_request
    quote_instance = form.save()
  File "/Users/edikeifeanyisamuel/Desktop/non_api_projects/welder/venv/lib/python3.13/site-packages/django/forms/models.py", line 554, in save
    self.instance.save()
    ~~~~~~~~~~~~~~~~~~^^
  File "/Users/edikeifeanyisamuel/Desktop/non_api_projects/welder/welding_project/main/models.py", line 186, in save
    self.tracking_id = f'WTP-{uuid.uuid4().hex[:8].upper()}'
                              ^^^^
NameError: name 'uuid' is not defined. Did you forget to import 'uuid'?
/Users/edikeifeanyisamuel/Desktop/non_api_projects/welder/welding_project/main/models.py changed, reloading.
Watching for file changes with StatReloader
/Users/edikeifeanyisamuel/Desktop/non_api_projects/welder/welding_project/main/views.py changed, reloading.
Watching for file changes with StatReloader
/Users/edikeifeanyisamuel/Desktop/non_api_projects/welder/welding_project/main/admin.py changed, reloading.
Watching for file changes with StatReloader
Internal Server Error: /admin/main/quoterequest/4/change/
Traceback (most recent call last):
  File "/Users/edikeifeanyisamuel/Desktop/non_api_projects/welder/venv/lib/python3.13/site-packages/django/contrib/admin/options.py", line 839, in get_form
    return modelform_factory(self.model, **defaults)
  File "/Users/edikeifeanyisamuel/Desktop/non_api_projects/welder/venv/lib/python3.13/site-packages/django/forms/models.py", line 654, in modelform_factory
    return type(form)(class_name, (form,), form_class_attrs)
           ~~~~~~~~~~^^^^^^^^^^^^^^^^^^^^^^^^^^^^^^^^^^^^^^^
  File "/Users/edikeifeanyisamuel/Desktop/non_api_projects/welder/venv/lib/python3.13/site-packages/django/forms/models.py", line 312, in __new__
    fields = fields_for_model(
        opts.model,
    ...<11 lines>...
        form_declared_fields=new_class.declared_fields,
    )
  File "/Users/edikeifeanyisamuel/Desktop/non_api_projects/welder/venv/lib/python3.13/site-packages/django/forms/models.py", line 207, in fields_for_model
    raise FieldError(
    ...<2 lines>...
    )
django.core.exceptions.FieldError: 'status_updated_at' cannot be specified for QuoteRequest model form as it is a non-editable field

During handling of the above exception, another exception occurred:

Traceback (most recent call last):
  File "/Users/edikeifeanyisamuel/Desktop/non_api_projects/welder/venv/lib/python3.13/site-packages/django/core/handlers/exception.py", line 55, in inner
    response = get_response(request)
  File "/Users/edikeifeanyisamuel/Desktop/non_api_projects/welder/venv/lib/python3.13/site-packages/django/core/handlers/base.py", line 197, in _get_response
    response = wrapped_callback(request, *callback_args, **callback_kwargs)
  File "/Users/edikeifeanyisamuel/Desktop/non_api_projects/welder/venv/lib/python3.13/site-packages/django/contrib/admin/options.py", line 718, in wrapper
    return self.admin_site.admin_view(view)(*args, **kwargs)
           ~~~~~~~~~~~~~~~~~~~~~~~~~~~~~~~~^^^^^^^^^^^^^^^^^
  File "/Users/edikeifeanyisamuel/Desktop/non_api_projects/welder/venv/lib/python3.13/site-packages/django/utils/decorators.py", line 188, in _view_wrapper
    result = _process_exception(request, e)
  File "/Users/edikeifeanyisamuel/Desktop/non_api_projects/welder/venv/lib/python3.13/site-packages/django/utils/decorators.py", line 186, in _view_wrapper
    response = view_func(request, *args, **kwargs)
  File "/Users/edikeifeanyisamuel/Desktop/non_api_projects/welder/venv/lib/python3.13/site-packages/django/views/decorators/cache.py", line 80, in _view_wrapper
    response = view_func(request, *args, **kwargs)
  File "/Users/edikeifeanyisamuel/Desktop/non_api_projects/welder/venv/lib/python3.13/site-packages/django/contrib/admin/sites.py", line 241, in inner
    return view(request, *args, **kwargs)
  File "/Users/edikeifeanyisamuel/Desktop/non_api_projects/welder/venv/lib/python3.13/site-packages/django/contrib/admin/options.py", line 1964, in change_view
    return self.changeform_view(request, object_id, form_url, extra_context)
           ~~~~~~~~~~~~~~~~~~~~^^^^^^^^^^^^^^^^^^^^^^^^^^^^^^^^^^^^^^^^^^^^^
  File "/Users/edikeifeanyisamuel/Desktop/non_api_projects/welder/venv/lib/python3.13/site-packages/django/utils/decorators.py", line 48, in _wrapper
    return bound_method(*args, **kwargs)
  File "/Users/edikeifeanyisamuel/Desktop/non_api_projects/welder/venv/lib/python3.13/site-packages/django/utils/decorators.py", line 188, in _view_wrapper
    result = _process_exception(request, e)
  File "/Users/edikeifeanyisamuel/Desktop/non_api_projects/welder/venv/lib/python3.13/site-packages/django/utils/decorators.py", line 186, in _view_wrapper
    response = view_func(request, *args, **kwargs)
  File "/Users/edikeifeanyisamuel/Desktop/non_api_projects/welder/venv/lib/python3.13/site-packages/django/contrib/admin/options.py", line 1820, in changeform_view
    return self._changeform_view(request, object_id, form_url, extra_context)
           ~~~~~~~~~~~~~~~~~~~~~^^^^^^^^^^^^^^^^^^^^^^^^^^^^^^^^^^^^^^^^^^^^^
  File "/Users/edikeifeanyisamuel/Desktop/non_api_projects/welder/venv/lib/python3.13/site-packages/django/contrib/admin/options.py", line 1855, in _changeform_view
    ModelForm = self.get_form(
        request, obj, change=not add, fields=flatten_fieldsets(fieldsets)
    )
  File "/Users/edikeifeanyisamuel/Desktop/non_api_projects/welder/venv/lib/python3.13/site-packages/django/contrib/admin/options.py", line 841, in get_form
    raise FieldError(
    ...<2 lines>...
    )
django.core.exceptions.FieldError: 'status_updated_at' cannot be specified for QuoteRequest model form as it is a non-editable field. Check fields/fieldsets/exclude attributes of class QuoteRequestAdmin.
/Users/edikeifeanyisamuel/Desktop/non_api_projects/welder/welding_project/main/admin.py changed, reloading.
Watching for file changes with StatReloader
